Traceback (most recent call last):
  File "c:\Users\Srikrishnan\miniconda3\envs\pytorch-gpu\lib\site-packages\wandb\sdk\wandb_config.py", line 165, in __getattr__
    return self.__getitem__(key)
  File "c:\Users\Srikrishnan\miniconda3\envs\pytorch-gpu\lib\site-packages\wandb\sdk\wandb_config.py", line 130, in __getitem__
    return self._items[key]
KeyError: 'loss'

The above exception was the direct cause of the following exception:

Traceback (most recent call last):
  File "C:\Users\Srikrishnan\AppData\Local\Temp\ipykernel_2116\2927767046.py", line 28, in train_wandb
    loss = Loss(loss_fn=config.loss)
  File "c:\Users\Srikrishnan\miniconda3\envs\pytorch-gpu\lib\site-packages\wandb\sdk\wandb_config.py", line 167, in __getattr__
    raise AttributeError(
AttributeError: <class 'wandb.sdk.wandb_config.Config'> object has no attribute 'loss'
